Workbook

Sheet Read Me
A1: SIMULATED CASE STUDY — FICTIONAL DATA — NOT ACTUAL CLIENT RESULTS
A3: Trading Performance Analysis – Sample Workbook
A4: Companion to Trading_Performance_Analysis_Sample_Report.pdf (portfolio demonstration).
A6: Sheets
A7: Trade Data: 40 fictional trades. Blue = typed inputs; black = formulas. Filters and frozen headers are on.
A8: Metrics & Definitions: every headline metric as a live formula, next to the value printed in the PDF and an OK/CHECK flag.
A9: Segments: results by setup, session, instrument, direction, rule status and risk status (COUNTIFS/SUMIFS formulas).
A11: Conventions
A12: 1R = planned risk on a trade = planned risk % x account equity before the trade (USD).
A13: Net result in R = Net P/L (USD) / 1R (USD). Win = net P/L above zero (after costs); loss = below zero.
A14: Drawdown in R and drawdown as % of account equity are different measures and are never mixed.
A15: Exposure = USD per 1.0 price unit (a simplification that avoids lot-size / pip-value conventions). Costs = round-turn spread x exposure.
... A22: All trades, dates, prices and account figures are fictional. Outcomes and rule flags were authored by the preparer. Not investment advice. No performance claim is made.

Sheet Trade Data
A1: SIMULATED CASE STUDY — FICTIONAL DATA — NOT ACTUAL CLIENT RESULTS
A2: Blue = input, black = formula. 1R = planned risk in USD. Prices are fictional.
A3: Trade ID | B3: Trade Date | C3: Instrument | D3: Session | E3: Setup | F3: Direction | G3: Entry Price | H3: Stop-Loss Price | I3: Take-Profit Price | J3: Planned Risk (% equity) | K3: Actual Risk (% equity) | L3: Gross P/L (USD) | M3: Transaction Costs (USD) | N3: Net P/L (USD) | O3: Net Result (R) | P3: Outcome | Q3: Planned Risk Exceeded | R3: Rule Violated | S3: Notes | T3: Exit Price | U3: Exit Type | V3: Exposure (USD per 1.0 price unit) | W3: Equity Before Trade (USD) | X3: Planned Risk 1R (USD) | Y3: Rule ID(s) | Z3: Cumulative R | AA3: Peak R | AB3: Drawdown (R) | AC3: Equity After Trade (USD) | AD3: Peak Equity (USD) | AE3: Drawdown (% of peak equity) | AF3: Win Streak | AG3: Loss Streak
A4: T01 | B4: 46083 | C4: USDJPY | D4: Asian | E4: Breakout | F4: Long | G4: 147.563 | H4: 147.109 | I4: 148.471 | J4: 1 | K4: =V4*ABS(G4-H4)/W4*100 -> 0.9999804 | L4: =ROUND(V4*IF(F4="Long",1,-1)*(T4-G4),2) -> 200 | M4: 2.2 | N4: =ROUND(L4-M4,2) -> 197.8 | O4: =N4/X4 -> 1.978 | P4: =IF(N4>0,"Win",IF(N4<0,"Loss","Breakeven")) -> Win | Q4: =IF(ROUND(K4,2)>ROUND(J4,2),"Yes","No") -> No | R4: No | S4: Plan followed | T4: 148.471 | U4: Target hit | V4: 220.26 | W4: 10000 | X4: =ROUND(W4*J4/100,2) -> 100 | Z4: =O4 -> 1.978 | AA4: =MAX(0,Z4) -> 1.978 | AB4: =Z4-AA4 -> 0 | AC4: =ROUND(W4+N4,2) -> 10197.8 | AD4: =MAX($W$4,AC4) -> 10197.8 | AE4: =(AC4-AD4)/AD4*100 -> 0 | AF4: =IF(O4>0,1,0) -> 1 | AG4: =IF(O4<0,1,0) -> 0
A5: T02 | B5: 46084 | C5: BTCUSD | D5: London | E5: Trend Pullback | F5: Short | G5: 66051.4 | H5: 67074.6 | I5: 64005 | J5: 0.5 | K5: =V5*ABS(G5-H5)/W5*100 -> 0.49967012 | L5: =ROUND(V5*IF(F5="Long",1,-1)*(T5-G5),2) -> -50.96 | M5: 0.75 | N5: =ROUND(L5-M5,2) -> -51.71 | O5: =N5/X5 -> -1.0141204 | P5: =IF(N5>0,"Win",IF(N5<0,"Loss","Breakeven")) -> Loss | Q5: =IF(ROUND(K5,2)>ROUND(J5,2),"Yes","No") -> No | R5: No | S5: Plan followed; stopped out | T5: 67074.6 | U5: Stop hit | V5: 0.0498 | W5: =ROUND(W4+N4,2) -> 10197.8 | X5: =ROUND(W5*J5/100,2) -> 50.99 | Z5: =Z4+O5 -> 0.96387958 | AA5: =MAX(AA4,Z5) -> 1.978 | AB5: =Z5-AA5 -> -1.0141204 | AC5: =ROUND(W5+N5,2) -> 10146.09 | AD5: =MAX(AD4,AC5) -> 10197.8 | AE5: =(AC5-AD5)/AD5*100 -> -0.50707015 | AF5: =IF(O5>0,AF4+1,0) -> 0 | AG5: =IF(O5<0,AG4+1,0) -> 1
A6: T03 | B6: 46084 | C6: XAUUSD | D6: London/NY Overlap | E6: Discretionary Other | F6: Short | G6: 2658.16 | H6: 2669.47 | I6: 2635.54 | J6: 1 | K6: =V6*ABS(G6-H6)/W6*100 -> 0.99989947 | L6: =ROUND(V6*IF(F6="Long",1,-1)*(T6-G6),2) -> -101.45 | M6: 2.24 | N6: =ROUND(L6-M6,2) -> -103.69 | O6: =N6/X6 -> -1.0219791 | P6: =IF(N6>0,"Win",IF(N6<0,"Loss","Breakeven")) -> Loss | Q6: =IF(ROUND(K6,2)>ROUND(J6,2),"Yes","No") -> No | R6: No | S6: Plan followed; stopped out | T6: 2669.47 | U6: Stop hit | V6: 8.97 | W6: =ROUND(W5+N5,2) -> 10146.09 | X6: =ROUND(W6*J6/100,2) -> 101.46 | Z6: =Z5+O6 -> -0.058099521 | AA6: =MAX(AA5,Z6) -> 1.978 | AB6: =Z6-AA6 -> -2.0360995 | AC6: =ROUND(W6+N6,2) -> 10042.4 | AD6: =MAX(AD5,AC6) -> 10197.8 | AE6: =(AC6-AD6)/AD6*100 -> -1.5238581 | AF6: =IF(O6>0,AF5+1,0) -> 0 | AG6: =IF(O6<0,AG5+1,0) -> 2
A7: T04 | B7: 46085 | C7: EURUSD | D7: London/NY Overlap | E7: Trend Pullback | F7: Long | G7: 1.07544 | H7: 1.07315 | I7: 1.0791 | J7: 1 | K7: =V7*ABS(G7-H7)/W7*100 -> 0.99995998 | L7: =ROUND(V7*IF(F7="Long",1,-1)*(T7-G7),2) -> 160.5 | M7: 3.51 | N7: =ROUND(L7-M7,2) -> 156.99 | O7: =N7/X7 -> 1.563334 | P7: =IF(N7>0,"Win",IF(N7<0,"Loss","Breakeven")) -> Win | Q7: =IF(ROUND(K7,2)>ROUND(J7,2),"Yes","No") -> No | R7: No | S7: Plan followed | T7: 1.0791 | U7: Target hit | V7: 43851.52 | W7: =ROUND(W6+N6,2) -> 10042.4 | X7: =ROUND(W7*J7/100,2) -> 100.42 | Z7: =Z6+O7 -> 1.5052345 | AA7: =MAX(AA6,Z7) -> 1.978 | AB7: =Z7-AA7 -> -0.47276552 | AC7: =ROUND(W7+N7,2) -> 10199.39 | AD7: =MAX(AD6,AC7) -> 10199.39 | AE7: =(AC7-AD7)/AD7*100 -> 0 | AF7: =IF(O7>0,AF6+1,0) -> 1 | AG7: =IF(O7<0,AG6+1,0) -> 0
A8: T05 | B8: 46087 | C8: EURUSD | D8: London/NY Overlap | E8: Trend Pullback | F8: Short | G8: 1.08123 | H8: 1.08412 | I8: 1.074 | J8: 1 | K8: =V8*ABS(G8-H8)/W8*100 -> 0.99996155 | L8: =ROUND(V8*IF(F8="Long",1,-1)*(T8-G8),2) -> -101.99 | M8: 2.82 | N8: =ROUND(L8-M8,2) -> -104.81 | O8: =N8/X8 -> -1.0276498 | P8: =IF(N8>0,"Win",IF(N8<0,"Loss","Breakeven")) -> Loss | Q8: =IF(ROUND(K8,2)>ROUND(J8,2),"Yes","No") -> No | R8: Yes | S8: Entered before confirmation candle closed; stopped out | T8: 1.08412 | U8: Stop hit | V8: 35290.65 | W8: =ROUND(W7+N7,2) -> 10199.39 | X8: =ROUND(W8*J8/100,2) -> 101.99 | Y8: R3 | Z8: =Z7+O8 -> 0.47758471 | AA8: =MAX(AA7,Z8) -> 1.978 | AB8: =Z8-AA8 -> -1.5004153 | AC8: =ROUND(W8+N8,2) -> 10094.58 | AD8: =MAX(AD7,AC8) -> 10199.39 | AE8: =(AC8-AD8)/AD8*100 -> -1.0276105 | AF8: =IF(O8>0,AF7+1,0) -> 0 | AG8: =IF(O8<0,AG7+1,0) -> 1
A9: T06 | B9: 46090 | C9: EURUSD | D9: London/NY Overlap | E9: Trend Pullback | F9: Short | G9: 1.085 | H9: 1.08799 | I9: 1.08051 | J9: 1 | K9: =V9*ABS(G9-H9)/W9*100 -> 1.0000416 | L9: =ROUND(V9*IF(F9="Long",1,-1)*(T9-G9),2) -> 151.59 | M9: 2.7 | N9: =ROUND(L9-M9,2) -> 148.89 | O9: =N9/X9 -> 1.4748886 | P9: =IF(N9>0,"Win",IF(N9<0,"Loss","Breakeven")) -> Win | Q9: =IF(ROUND(K9,2)>ROUND(J9,2),"Yes","No") -> No | R9: No | S9: Plan followed | T9: 1.08051 | U9: Target hit | V9: 33762.54 | W9: =ROUND(W8+N8,2) -> 10094.58 | X9: =ROUND(W9*J9/100,2) -> 100.95 | Z9: =Z8+O9 -> 1.9524733 | AA9: =MAX(AA8,Z9) -> 1.978 | AB9: =Z9-AA9 -> -0.025526735 | AC9: =ROUND(W9+N9,2) -> 10243.47 | AD9: =MAX(AD8,AC9) -> 10243.47 | AE9: =(AC9-AD9)/AD9*100 -> 0 | AF9: =IF(O9>0,AF8+1,0) -> 1 | AG9: =IF(O9<0,AG8+1,0) -> 0
A10: T07 | B10: 46091 | C10: USDJPY | D10: London/NY Overlap | E10: Breakout | F10: Long | G10: 149.117 | H10: 148.722 | I10: 150.105 | J10: 1 | K10: =V10*ABS(G10-H10)/W10*100 -> 0.99992922 | L10: =ROUND(V10*IF(F10="Long",1,-1)*(T10-G10),2) -> -102.43 | M10: 2.59 | N10: =ROUND(L10-M10,2) -> -105.02 | O10: =N10/X10 -> -1.0252856 | P10: =IF(N10>0,"Win",IF(N10<0,"Loss","Breakeven")) -> Loss | Q10: =IF(ROUND(K10,2)>ROUND(J10,2),"Yes","No") -> No | R10: No | S10: Plan followed; stopped out | T10: 148.722 | U10: Stop hit | V10: 259.31 | W10: =ROUND(W9+N9,2) -> 10243.47 | X10: =ROUND(W10*J10/100,2) -> 102.43 | Z10: =Z9+O10 -> 0.9271877 | AA10: =MAX(AA9,Z10) -> 1.978 | AB10: =Z10-AA10 -> -1.0508123 | AC10: =ROUND(W10+N10,2) -> 10138.45 | AD10: =MAX(AD9,AC10) -> 10243.47 | AE10: =(AC10-AD10)/AD10*100 -> -1.0252385 | AF10: =IF(O10>0,AF9+1,0) -> 0 | AG10: =IF(O10<0,AG9+1,0) -> 1
A11: T08 | B11: 46092 | C11: EURUSD | D11: London/NY Overlap | E11: Trend Pullback | F11: Long | G11: 1.08637 | H11: 1.08421 | I11: 1.09069 | J11: 1 | K11: =V11*ABS(G11-H11)/W11*100 -> 0.9999555 | L11: =ROUND(V11*IF(F11="Long",1,-1)*(T11-G11),2) -> 81.2 | M11: 3.75 | N11: =ROUND(L11-M11,2) -> 77.45 | O11: =N11/X11 -> 0.76395739 | P11: =IF(N11>0,"Win",IF(N11<0,"Loss","Breakeven")) -> Win | Q11: =IF(ROUND(K11,2)>ROUND(J11,2),"Yes","No") -> No | R11: Yes | S11: Closed manually well before target; no trail documented | T11: 1.0881 | U11: Manual early exit | V11: 46935.18 | W11: =ROUND(W10+N10,2) -> 10138.45 | X11: =ROUND(W11*J11/100,2) -> 101.38 | Y11: R4 | Z11: =Z10+O11 -> 1.6911451 | AA11: =MAX(AA10,Z11) -> 1.978 | AB11: =Z11-AA11 -> -0.28685491 | AC11: =ROUND(W11+N11,2) -> 10215.9 | AD11: =MAX(AD10,AC11) -> 10243.47 | AE11: =(AC11-AD11)/AD11*100 -> -0.26914708 | AF11: =IF(O11>0,AF10+1,0) -> 1 | AG11: =IF(O11<0,AG10+1,0) -> 0
A12: T09 | B12: 46093 | C12: XAUUSD | D12: New York | E12: Breakout | F12: Long | G12: 2668.41 | H12: 2661.41 | I12: 2685.91 | J12: 1 | K12: =V12*ABS(G12-H12)/W12*100 -> 0.99971613 | L12: =ROUND(V12*IF(F12="Long",1,-1)*(T12-G12),2) -> -102.13 | M12: 3.65 | N12: =ROUND(L12-M12,2) -> -105.78 | O12: =N12/X12 -> -1.0354346 | P12: =IF(N12>0,"Win",IF(N12<0,"Loss","Breakeven")) -> Loss | Q12: =IF(ROUND(K12,2)>ROUND(J12,2),"Yes","No") -> No | R12: No | S12: Plan followed; stopped out | T12: 2661.41 | U12: Stop hit | V12: 14.59 | W12: =ROUND(W11+N11,2) -> 10215.9 | X12: =ROUND(W12*J12/100,2) -> 102.16 | Z12: =Z11+O12 -> 0.65571048 | AA12: =MAX(AA11,Z12) -> 1.978 | AB12: =Z12-AA12 -> -1.3222895 | AC12: =ROUND(W12+N12,2) -> 10110.12 | AD12: =MAX(AD11,AC12) -> 10243.47 | AE12: =(AC12-AD12)/AD12*100 -> -1.301805 | AF12: =IF(O12>0,AF11+1,0) -> 0 | AG12: =IF(O12<0,AG11+1,0) -> 1
A13: T10 | B13: 46094 | C13: EURUSD | D13: London | E13: Breakout | F13: Short | G13: 1.08326 | H13: 1.08611 | I13: 1.07756 | J13: 1 | K13: =V13*ABS(G13-H13)/W13*100 -> 0.99998801 | L13: =ROUND(V13*IF(F13="Long",1,-1)*(T13-G13),2) -> -101.1 | M13: 2.84 | N13: =ROUND(L13-M13,2) -> -103.94 | O13: =N13/X13 -> -1.028091 | P13: =IF(N13>0,"Win",IF(N13<0,"Loss","Breakeven")) -> Loss | Q13: =IF(ROUND(K13,2)>ROUND(J13,2),"Yes","No") -> No | R13: No | S13: Plan followed; stopped out | T13: 1.08611 | U13: Stop hit | V13: 35473.68 | W13: =ROUND(W12+N12,2) -> 10110.12 | X13: =ROUND(W13*J13/100,2) -> 101.1 | Z13: =Z12+O13 -> -0.37238052 | AA13: =MAX(AA12,Z13) -> 1.978 | AB13: =Z13-AA13 -> -2.3503805 | AC13: =ROUND(W13+N13,2) -> 10006.18 | AD13: =MAX(AD12,AC13) -> 10243.47 | AE13: =(AC13-AD13)/AD13*100 -> -2.3165002 | AF13: =IF(O13>0,AF12+1,0) -> 0 | AG13: =IF(O13<0,AG12+1,0) -> 2
A14: T11 | B14: 46097 | C14: EURUSD | D14: London/NY Overlap | E14: Trend Pullback | F14: Long | G14: 1.0809 | H14: 1.07888 | I14: 1.08534 | J14: 1 | K14: =V14*ABS(G14-H14)/W14*100 -> 0.99998194 | L14: =ROUND(V14*IF(F14="Long",1,-1)*(T14-G14),2) -> 219.93 | M14: 3.96 | N14: =ROUND(L14-M14,2) -> 215.97 | O14: =N14/X14 -> 2.158405 | P14: =IF(N14>0,"Win",IF(N14<0,"Loss","Breakeven")) -> Win | Q14: =IF(ROUND(K14,2)>ROUND(J14,2),"Yes","No") -> No | R14: No | S14: Plan followed | T14: 1.08534 | U14: Target hit | V14: 49534.65 | W14: =ROUND(W13+N13,2) -> 10006.18 | X14: =ROUND(W14*J14/100,2) -> 100.06 | Z14: =Z13+O14 -> 1.7860244 | AA14: =MAX(AA13,Z14) -> 1.978 | AB14: =Z14-AA14 -> -0.19197556 | AC14: =ROUND(W14+N14,2) -> 10222.15 | AD14: =MAX(AD13,AC14) -> 10243.47 | AE14: =(AC14-AD14)/AD14*100 -> -0.2081326 | AF14: =IF(O14>0,AF13+1,0) -> 1 | AG14: =IF(O14<0,AG13+1,0) -> 0
A15: T12 | B15: 46099 | C15: USDJPY | D15: London | E15: Trend Pullback | F15: Long | G15: 147.048 | H15: 146.609 | I15: 147.707 | J15: 1 | K15: =V15*ABS(G15-H15)/W15*100 -> 0.99995363 | L15: =ROUND(V15*IF(F15="Long",1,-1)*(T15-G15),2) -> -102.22 | M15: 2.33 | N15: =ROUND(L15-M15,2) -> -104.55 | O15: =N15/X15 -> -1.022794 | P15: =IF(N15>0,"Win",IF(N15<0,"Loss","Breakeven")) -> Loss | Q15: =IF(ROUND(K15,2)>ROUND(J15,2),"Yes","No") -> No | R15: Unclear | S15: Journal does not say whether stop was moved; record incomplete | T15: 146.609 | U15: Stop hit | V15: 232.84 | W15: =ROUND(W14+N14,2) -> 10222.15 | X15: =ROUND(W15*J15/100,2) -> 102.22 | Y15: R4? | Z15: =Z14+O15 -> 0.76323046 | AA15: =MAX(AA14,Z15) -> 1.978 | AB15: =Z15-AA15 -> -1.2147695 | AC15: =ROUND(W15+N15,2) -> 10117.6 | AD15: =MAX(AD14,AC15) -> 10243.47 | AE15: =(AC15-AD15)/AD15*100 -> -1.2287828 | AF15: =IF(O15>0,AF14+1,0) -> 0 | AG15: =IF(O15<0,AG14+1,0) -> 1
A16: T13 | B16: 46100 | C16: USDJPY | D16: New York | E16: Range Reversal | F16: Long | G16: 148.344 | H16: 147.987 | I16: N/A | J16: 1 | K16: =V16*ABS(G16-H16)/W16*100 -> 1.0000135 | L16: =ROUND(V16*IF(F16="Long",1,-1)*(T16-G16),2) -> 151.91 | M16: 2.83 | N16: =ROUND(L16-M16,2) -> 149.08 | O16: =N16/X16 -> 1.4734137 | P16: =IF(N16>0,"Win",IF(N16<0,"Loss","Breakeven")) -> Win | Q16: =IF(ROUND(K16,2)>ROUND(J16,2),"Yes","No") -> No | R16: No | S16: Plan followed | T16: 148.88 | U16: Trailing stop (documented) | V16: 283.41 | W16: =ROUND(W15+N15,2) -> 10117.6 | X16: =ROUND(W16*J16/100,2) -> 101.18 | Z16: =Z15+O16 -> 2.2366442 | AA16: =MAX(AA15,Z16) -> 2.2366442 | AB16: =Z16-AA16 -> 0 | AC16: =ROUND(W16+N16,2) -> 10266.68 | AD16: =MAX(AD15,AC16) -> 10266.68 | AE16: =(AC16-AD16)/AD16*100 -> 0 | AF16: =IF(O16>0,AF15+1,0) -> 1 | AG16: =IF(O16<0,AG15+1,0) -> 0
A17: T14 | B17: 46100 | C17: BTCUSD | D17: Asian | E17: Range Reversal | F17: Long | G17: 67560.6 | H17: 66630.3 | I17: 69421.2 | J17: 0.5 | K17: =V17*ABS(G17-H17)/W17*100 -> 0.49928049 | L17: =ROUND(V17*IF(F17="Long",1,-1)*(T17-G17),2) -> -56.38 | M17: 0.83 | N17: =ROUND(L17-M17,2) -> -57.21 | O17: =N17/X17 -> -1.1145529 | P17: =IF(N17>0,"Win",IF(N17<0,"Loss","Breakeven")) -> Loss | Q17: =IF(ROUND(K17,2)>ROUND(J17,2),"Yes","No") -> No | R17: Yes | S17: Asian-session entry on non-JPY pair; gap through stop (slippage) | T17: 66537.3 | U17: Stop hit (slippage) | V17: 0.0551 | W17: =ROUND(W16+N16,2) -> 10266.68 | X17: =ROUND(W17*J17/100,2) -> 51.33 | Y17: R2 | Z17: =Z16+O17 -> 1.1220913 | AA17: =MAX(AA16,Z17) -> 2.2366442 | AB17: =Z17-AA17 -> -1.1145529 | AC17: =ROUND(W17+N17,2) -> 10209.47 | AD17: =MAX(AD16,AC17) -> 10266.68 | AE17: =(AC17-AD17)/AD17*100 -> -0.55723954 | AF17: =IF(O17>0,AF16+1,0) -> 0 | AG17: =IF(O17<0,AG16+1,0) -> 1
A18: T15 | B18: 46101 | C18: USDJPY | D18: Asian | E18: Discretionary Other | F18: Long | G18: 147.816 | H18: 147.225 | I18: 148.703 | J18: 1 | K18: =V18*ABS(G18-H18)/W18*100 -> 0.9999475 | L18: =ROUND(V18*IF(F18="Long",1,-1)*(T18-G18),2) -> -102.09 | M18: 1.73 | N18: =ROUND(L18-M18,2) -> -103.82 | O18: =N18/X18 -> -1.0169458 | P18: =IF(N18>0,"Win",IF(N18<0,"Loss","Breakeven")) -> Loss | Q18: =IF(ROUND(K18,2)>ROUND(J18,2),"Yes","No") -> No | R18: No | S18: Plan followed; stopped out | T18: 147.225 | U18: Stop hit | V18: 172.74 | W18: =ROUND(W17+N17,2) -> 10209.47 | X18: =ROUND(W18*J18/100,2) -> 102.09 | Z18: =Z17+O18 -> 0.10514546 | AA18: =MAX(AA17,Z18) -> 2.2366442 | AB18: =Z18-AA18 -> -2.1314987 | AC18: =ROUND(W18+N18,2) -> 10105.65 | AD18: =MAX(AD17,AC18) -> 10266.68 | AE18: =(AC18-AD18)/AD18*100 -> -1.568472 | AF18: =IF(O18>0,AF17+1,0) -> 0 | AG18: =IF(O18<0,AG17+1,0) -> 2
A19: T16 | B19: 46104 | C19: BTCUSD | D19: New York | E19: Discretionary Other | F19: Long | G19: 66426.3 | H19: 65489.7 | I19: 68299.5 | J19: 0.5 | K19: =V19*ABS(G19-H19)/W19*100 -> 0.49954966 | L19: =ROUND(V19*IF(F19="Long",1,-1)*(T19-G19),2) -> 100.97 | M19: 0.81 | N19: =ROUND(L19-M19,2) -> 100.16 | O19: =N19/X19 -> 1.9821888 | P19: =IF(N19>0,"Win",IF(N19<0,"Loss","Breakeven")) -> Win | Q19: =IF(ROUND(K19,2)>ROUND(J19,2),"Yes","No") -> No | R19: No | S19: Plan followed | T19: 68299.5 | U19: Target hit | V19: 0.0539 | W19: =ROUND(W18+N18,2) -> 10105.65 | X19: =ROUND(W19*J19/100,2) -> 50.53 | Z19: =Z18+O19 -> 2.0873343 | AA19: =MAX(AA18,Z19) -> 2.2366442 | AB19: =Z19-AA19 -> -0.14930993 | AC19: =ROUND(W19+N19,2) -> 10205.81 | AD19: =MAX(AD18,AC19) -> 10266.68 | AE19: =(AC19-AD19)/AD19*100 -> -0.59288884 | AF19: =IF(O19>0,AF18+1,0) -> 1 | AG19: =IF(O19<0,AG18+1,0) -> 0
A20: T17 | B20: 46105 | C20: BTCUSD | D20: London/NY Overlap | E20: Breakout | F20: Long | G20: 70661.8 | H20: 69833.9 | I20: 72317.6 | J20: 0.5 | K20: =V20*ABS(G20-H20)/W20*100 -> 0.49970203 | L20: =ROUND(V20*IF(F20="Long",1,-1)*(T20-G20),2) -> -51 | M20: 0.92 | N20: =ROUND(L20-M20,2) -> -51.92 | O20: =N20/X20 -> -1.0174407 | P20: =IF(N20>0,"Win",IF(N20<0,"Loss","Breakeven")) -> Loss | Q20: =IF(ROUND(K20,2)>ROUND(J20,2),"Yes","No") -> No | R20: No | S20: Plan followed; stopped out | T20: 69833.9 | U20: Stop hit | V20: 0.0616 | W20: =ROUND(W19+N19,2) -> 10205.81 | X20: =ROUND(W20*J20/100,2) -> 51.03 | Z20: =Z19+O20 -> 1.0698935 | AA20: =MAX(AA19,Z20) -> 2.2366442 | AB20: =Z20-AA20 -> -1.1667506 | AC20: =ROUND(W20+N20,2) -> 10153.89 | AD20: =MAX(AD19,AC20) -> 10266.68 | AE20: =(AC20-AD20)/AD20*100 -> -1.0986025 | AF20: =IF(O20>0,AF19+1,0) -> 0 | AG20: =IF(O20<0,AG19+1,0) -> 1
A21: T18 | B21: 46105 | C21: GBPUSD | D21: London | E21: Range Reversal | F21: Short | G21: 1.29852 | H21: 1.30179 | I21: 1.29198 | J21: 1 | K21: =V21*ABS(G21-H21)/W21*100 -> 1.0000106 | L21: =ROUND(V21*IF(F21="Long",1,-1)*(T21-G21),2) -> -101.54 | M21: 3.73 | N21: =ROUND(L21-M21,2) -> -105.27 | O21: =N21/X21 -> -1.0367343 | P21: =IF(N21>0,"Win",IF(N21<0,"Loss","Breakeven")) -> Loss | Q21: =IF(ROUND(K21,2)>ROUND(J21,2),"Yes","No") -> No | R21: No | S21: Plan followed; stopped out | T21: 1.30179 | U21: Stop hit | V21: 31051.98 | W21: =ROUND(W20+N20,2) -> 10153.89 | X21: =ROUND(W21*J21/100,2) -> 101.54 | Z21: =Z20+O21 -> 0.033159243 | AA21: =MAX(AA20,Z21) -> 2.2366442 | AB21: =Z21-AA21 -> -2.2034849 | AC21: =ROUND(W21+N21,2) -> 10048.62 | AD21: =MAX(AD20,AC21) -> 10266.68 | AE21: =(AC21-AD21)/AD21*100 -> -2.1239583 | AF21: =IF(O21>0,AF20+1,0) -> 0 | AG21: =IF(O21<0,AG20+1,0) -> 2
A22: T19 | B22: 46105 | C22: XAUUSD | D22: London | E22: Trend Pullback | F22: Long | G22: 2624.32 | H22: 2614.74 | I22: 2643.48 | J22: 1 | K22: =V22*ABS(G22-H22)/W22*100 -> 1.4996427 | L22: =ROUND(V22*IF(F22="Long",1,-1)*(T22-G22),2) -> -150.69 | M22: 3.93 | N22: =ROUND(L22-M22,2) -> -154.62 | O22: =N22/X22 -> -1.5386606 | P22: =IF(N22>0,"Win",IF(N22<0,"Loss","Breakeven")) -> Loss | Q22: =IF(ROUND(K22,2)>ROUND(J22,2),"Yes","No") -> Yes | R22: Yes | S22: Third trade of the day after two losses; position oversized | T22: 2614.74 | U22: Stop hit | V22: 15.73 | W22: =ROUND(W21+N21,2) -> 10048.62 | X22: =ROUND(W22*J22/100,2) -> 100.49 | Y22: R1, R5 | Z22: =Z21+O22 -> -1.5055013 | AA22: =MAX(AA21,Z22) -> 2.2366442 | AB22: =Z22-AA22 -> -3.7421455 | AC22: =ROUND(W22+N22,2) -> 9894 | AD22: =MAX(AD21,AC22) -> 10266.68 | AE22: =(AC22-AD22)/AD22*100 -> -3.6299953 | AF22: =IF(O22>0,AF21+1,0) -> 0 | AG22: =IF(O22<0,AG21+1,0) -> 3
A23: T20 | B23: 46107 | C23: BTCUSD | D23: New York | E23: Trend Pullback | F23: Short | G23: 69808 | H23: 70589.4 | I23: 68323.3 | J23: 0.5 | K23: =V23*ABS(G23-H23)/W23*100 -> 0.49992541 | L23: =ROUND(V23*IF(F23="Long",1,-1)*(T23-G23),2) -> 93.98 | M23: 0.95 | N23: =ROUND(L23-M23,2) -> 93.03 | O23: =N23/X23 -> 1.8805337 | P23: =IF(N23>0,"Win",IF(N23<0,"Loss","Breakeven")) -> Win | Q23: =IF(ROUND(K23,2)>ROUND(J23,2),"Yes","No") -> No | R23: No | S23: Plan followed | T23: 68323.3 | U23: Target hit | V23: 0.0633 | W23: =ROUND(W22+N22,2) -> 9894 | X23: =ROUND(W23*J23/100,2) -> 49.47 | Z23: =Z22+O23 -> 0.37503234 | AA23: =MAX(AA22,Z23) -> 2.2366442 | AB23: =Z23-AA23 -> -1.8616118 | AC23: =ROUND(W23+N23,2) -> 9987.03 | AD23: =MAX(AD22,AC23) -> 10266.68 | AE23: =(AC23-AD23)/AD23*100 -> -2.7238601 | AF23: =IF(O23>0,AF22+1,0) -> 1 | AG23: =IF(O23<0,AG22+1,0) -> 0
A24: T21 | B24: 46108 | C24: USDJPY | D24: New York | E24: Breakout | F24: Short | G24: 149.713 | H24: 150.258 | I24: 148.35 | J24: 1 | K24: =V24*ABS(G24-H24)/W24*100 -> 0.99995494 | L24: =ROUND(V24*IF(F24="Long",1,-1)*(T24-G24),2) -> -99.87 | M24: 1.83 | N24: =ROUND(L24-M24,2) -> -101.7 | O24: =N24/X24 -> -1.0183238 | P24: =IF(N24>0,"Win",IF(N24<0,"Loss","Breakeven")) -> Loss | Q24: =IF(ROUND(K24,2)>ROUND(J24,2),"Yes","No") -> No | R24: No | S24: Plan followed; stopped out | T24: 150.258 | U24: Stop hit | V24: 183.24 | W24: =ROUND(W23+N23,2) -> 9987.03 | X24: =ROUND(W24*J24/100,2) -> 99.87 | Z24: =Z23+O24 -> -0.64329148 | AA24: =MAX(AA23,Z24) -> 2.2366442 | AB24: =Z24-AA24 -> -2.8799357 | AC24: =ROUND(W24+N24,2) -> 9885.33 | AD24: =MAX(AD23,AC24) -> 10266.68 | AE24: =(AC24-AD24)/AD24*100 -> -3.7144432 | AF24: =IF(O24>0,AF23+1,0) -> 0 | AG24: =IF(O24<0,AG23+1,0) -> 1
A25: T22 | B25: 46111 | C25: EURUSD | D25: London/NY Overlap | E25: Trend Pullback | F25: Long | G25: 1.08906 | H25: 1.08648 | I25: 1.09319 | J25: 1 | K25: =V25*ABS(G25-H25)/W25*100 -> 0.99996653 | L25: =ROUND(V25*IF(F25="Long",1,-1)*(T25-G25),2) -> 158.24 | M25: 3.07 | N25: =ROUND(L25-M25,2) -> 155.17 | O25: =N25/X25 -> 1.5697521 | P25: =IF(N25>0,"Win",IF(N25<0,"Loss","Breakeven")) -> Win | Q25: =IF(ROUND(K25,2)>ROUND(J25,2),"Yes","No") -> No | R25: No | S25: Plan followed | T25: 1.09319 | U25: Target hit | V25: 38313.95 | W25: =ROUND(W24+N24,2) -> 9885.33 | X25: =ROUND(W25*J25/100,2) -> 98.85 | Z25: =Z24+O25 -> 0.92646067 | AA25: =MAX(AA24,Z25) -> 2.2366442 | AB25: =Z25-AA25 -> -1.3101835 | AC25: =ROUND(W25+N25,2) -> 10040.5 | AD25: =MAX(AD24,AC25) -> 10266.68 | AE25: =(AC25-AD25)/AD25*100 -> -2.2030491 | AF25: =IF(O25>0,AF24+1,0) -> 1 | AG25: =IF(O25<0,AG24+1,0) -> 0
A26: T23 | B26: 46112 | C26: USDJPY | D26: London | E26: Breakout | F26: Long | G26: 147.339 | H26: 146.885 | I26: 148.247 | J26: 1 | K26: =V26*ABS(G26-H26)/W26*100 -> 1.0000163 | L26: =ROUND(V26*IF(F26="Long",1,-1)*(T26-G26),2) -> 40.25 | M26: 2.21 | N26: =ROUND(L26-M26,2) -> 38.04 | O26: =N26/X26 -> 0.37884673 | P26: =IF(N26>0,"Win",IF(N26<0,"Loss","Breakeven")) -> Win | Q26: =IF(ROUND(K26,2)>ROUND(J26,2),"Yes","No") -> No | R26: Yes | S26: Manual early exit at small gain; no trail documented | T26: 147.521 | U26: Manual early exit | V26: 221.16 | W26: =ROUND(W25+N25,2) -> 10040.5 | X26: =ROUND(W26*J26/100,2) -> 100.41 | Y26: R4 | Z26: =Z25+O26 -> 1.3053074 | AA26: =MAX(AA25,Z26) -> 2.2366442 | AB26: =Z26-AA26 -> -0.93133679 | AC26: =ROUND(W26+N26,2) -> 10078.54 | AD26: =MAX(AD25,AC26) -> 10266.68 | AE26: =(AC26-AD26)/AD26*100 -> -1.8325301 | AF26: =IF(O26>0,AF25+1,0) -> 2 | AG26: =IF(O26<0,AG25+1,0) -> 0
A27: T24 | B27: 46113 | C27: GBPUSD | D27: London | E27: Range Reversal | F27: Short | G27: 1.28373 | H27: 1.28788 | I27: 1.27543 | J27: 1 | K27: =V27*ABS(G27-H27)/W27*100 -> 1.0000454 | L27: =ROUND(V27*IF(F27="Long",1,-1)*(T27-G27),2) -> -100.79 | M27: 2.91 | N27: =ROUND(L27-M27,2) -> -103.7 | O27: =N27/X27 -> -1.0288719 | P27: =IF(N27>0,"Win",IF(N27<0,"Loss","Breakeven")) -> Loss | Q27: =IF(ROUND(K27,2)>ROUND(J27,2),"Yes","No") -> No | R27: No | S27: Plan followed; stopped out | T27: 1.28788 | U27: Stop hit | V27: 24286.74 | W27: =ROUND(W26+N26,2) -> 10078.54 | X27: =ROUND(W27*J27/100,2) -> 100.79 | Z27: =Z26+O27 -> 0.27643548 | AA27: =MAX(AA26,Z27) -> 2.2366442 | AB27: =Z27-AA27 -> -1.9602087 | AC27: =ROUND(W27+N27,2) -> 9974.84 | AD27: =MAX(AD26,AC27) -> 10266.68 | AE27: =(AC27-AD27)/AD27*100 -> -2.8425937 | AF27: =IF(O27>0,AF26+1,0) -> 0 | AG27: =IF(O27<0,AG26+1,0) -> 1
A28: T25 | B28: 46114 | C28: BTCUSD | D28: New York | E28: Trend Pullback | F28: Long | G28: 70335 | H28: 69048.7 | I28: 72907.6 | J28: 0.5 | K28: =V28*ABS(G28-H28)/W28*100 -> 0.5390296 | L28: =ROUND(V28*IF(F28="Long",1,-1)*(T28-G28),2) -> 107.53 | M28: 0.63 | N28: =ROUND(L28-M28,2) -> 106.9 | O28: =N28/X28 -> 2.1435733 | P28: =IF(N28>0,"Win",IF(N28<0,"Loss","Breakeven")) -> Win | Q28: =IF(ROUND(K28,2)>ROUND(J28,2),"Yes","No") -> Yes | R28: No | S28: Size slightly above plan (within ±10% tolerance) | T28: 72907.6 | U28: Target hit | V28: 0.0418 | W28: =ROUND(W27+N27,2) -> 9974.84 | X28: =ROUND(W28*J28/100,2) -> 49.87 | Z28: =Z27+O28 -> 2.4200088 | AA28: =MAX(AA27,Z28) -> 2.4200088 | AB28: =Z28-AA28 -> 0 | AC28: =ROUND(W28+N28,2) -> 10081.74 | AD28: =MAX(AD27,AC28) -> 10266.68 | AE28: =(AC28-AD28)/AD28*100 -> -1.8013613 | AF28: =IF(O28>0,AF27+1,0) -> 1 | AG28: =IF(O28<0,AG27+1,0) -> 0
A29: T26 | B29: 46115 | C29: EURUSD | D29: Asian | E29: Trend Pullback | F29: Short | G29: 1.08629 | H29: 1.08957 | I29: 1.07809 | J29: 1 | K29: =V29*ABS(G29-H29)/W29*100 -> 1.0000256 | L29: =ROUND(V29*IF(F29="Long",1,-1)*(T29-G29),2) -> -100.82 | M29: 2.46 | N29: =ROUND(L29-M29,2) -> -103.28 | O29: =N29/X29 -> -1.0243999 | P29: =IF(N29>0,"Win",IF(N29<0,"Loss","Breakeven")) -> Loss | Q29: =IF(ROUND(K29,2)>ROUND(J29,2),"Yes","No") -> No | R29: Yes | S29: Asian-session entry on non-JPY pair | T29: 1.08957 | U29: Stop hit | V29: 30737.8 | W29: =ROUND(W28+N28,2) -> 10081.74 | X29: =ROUND(W29*J29/100,2) -> 100.82 | Y29: R2 | Z29: =Z28+O29 -> 1.3956089 | AA29: =MAX(AA28,Z29) -> 2.4200088 | AB29: =Z29-AA29 -> -1.0243999 | AC29: =ROUND(W29+N29,2) -> 9978.46 | AD29: =MAX(AD28,AC29) -> 10266.68 | AE29: =(AC29-AD29)/AD29*100 -> -2.807334 | AF29: =IF(O29>0,AF28+1,0) -> 0 | AG29: =IF(O29<0,AG28+1,0) -> 1
A30: T27 | B30: 46119 | C30: BTCUSD | D30: London | E30: Trend Pullback | F30: Long | G30: 69354.5 | H30: 68613 | I30: N/A | J30: 0.5 | K30: =V30*ABS(G30-H30)/W30*100 -> 0.49936363 | L30: =ROUND(V30*IF(F30="Long",1,-1)*(T30-G30),2) -> 59.79 | M30: 1.01 | N30: =ROUND(L30-M30,2) -> 58.78 | O30: =N30/X30 -> 1.178192 | P30: =IF(N30>0,"Win",IF(N30<0,"Loss","Breakeven")) -> Win | Q30: =IF(ROUND(K30,2)>ROUND(J30,2),"Yes","No") -> No | R30: No | S30: Plan followed | T30: 70244.3 | U30: Trailing stop (documented) | V30: 0.0672 | W30: =ROUND(W29+N29,2) -> 9978.46 | X30: =ROUND(W30*J30/100,2) -> 49.89 | Z30: =Z29+O30 -> 2.5738009 | AA30: =MAX(AA29,Z30) -> 2.5738009 | AB30: =Z30-AA30 -> 0 | AC30: =ROUND(W30+N30,2) -> 10037.24 | AD30: =MAX(AD29,AC30) -> 10266.68 | AE30: =(AC30-AD30)/AD30*100 -> -2.2348023 | AF30: =IF(O30>0,AF29+1,0) -> 1 | AG30: =IF(O30<0,AG29+1,0) -> 0
A31: T28 | B31: 46120 | C31: USDJPY | D31: Asian | E31: Trend Pullback | F31: Long | G31: 147.538 | H31: 147.127 | I31: 148.566 | J31: 1 | K31: =V31*ABS(G31-H31)/W31*100 -> 0.99993823 | L31: =ROUND(V31*IF(F31="Long",1,-1)*(T31-G31),2) -> -100.37 | M31: 2.44 | N31: =ROUND(L31-M31,2) -> -102.81 | O31: =N31/X31 -> -1.0243101 | P31: =IF(N31>0,"Win",IF(N31<0,"Loss","Breakeven")) -> Loss | Q31: =IF(ROUND(K31,2)>ROUND(J31,2),"Yes","No") -> No | R31: No | S31: Plan followed; stopped out | T31: 147.127 | U31: Stop hit | V31: 244.2 | W31: =ROUND(W30+N30,2) -> 10037.24 | X31: =ROUND(W31*J31/100,2) -> 100.37 | Z31: =Z30+O31 -> 1.5494908 | AA31: =MAX(AA30,Z31) -> 2.5738009 | AB31: =Z31-AA31 -> -1.0243101 | AC31: =ROUND(W31+N31,2) -> 9934.43 | AD31: =MAX(AD30,AC31) -> 10266.68 | AE31: =(AC31-AD31)/AD31*100 -> -3.2361971 | AF31: =IF(O31>0,AF30+1,0) -> 0 | AG31: =IF(O31<0,AG30+1,0) -> 1
A32: T29 | B32: 46121 | C32: BTCUSD | D32: London | E32: Trend Pullback | F32: Long | G32: 70126.7 | H32: 68838.4 | I32: 72059.1 | J32: 0.5 | K32: =V32*ABS(G32-H32)/W32*100 -> 0.49926921 | L32: =ROUND(V32*IF(F32="Long",1,-1)*(T32-G32),2) -> -49.6 | M32: 0.58 | N32: =ROUND(L32-M32,2) -> -50.18 | O32: =N32/X32 -> -1.0102678 | P32: =IF(N32>0,"Win",IF(N32<0,"Loss","Breakeven")) -> Loss | Q32: =IF(ROUND(K32,2)>ROUND(J32,2),"Yes","No") -> No | R32: No | S32: Plan followed; stopped out | T32: 68838.4 | U32: Stop hit | V32: 0.0385 | W32: =ROUND(W31+N31,2) -> 9934.43 | X32: =ROUND(W32*J32/100,2) -> 49.67 | Z32: =Z31+O32 -> 0.53922305 | AA32: =MAX(AA31,Z32) -> 2.5738009 | AB32: =Z32-AA32 -> -2.0345778 | AC32: =ROUND(W32+N32,2) -> 9884.25 | AD32: =MAX(AD31,AC32) -> 10266.68 | AE32: =(AC32-AD32)/AD32*100 -> -3.7249627 | AF32: =IF(O32>0,AF31+1,0) -> 0 | AG32: =IF(O32<0,AG31+1,0) -> 2
A33: T30 | B33: 46121 | C33: BTCUSD | D33: London/NY Overlap | E33: Discretionary Other | F33: Long | G33: 70304.3 | H33: 69319.4 | I33: 72077.1 | J33: 0.5 | K33: =V33*ABS(G33-H33)/W33*100 -> 0.49921329 | L33: =ROUND(V33*IF(F33="Long",1,-1)*(T33-G33),2) -> 88.82 | M33: 0.75 | N33: =ROUND(L33-M33,2) -> 88.07 | O33: =N33/X33 -> 1.782072 | P33: =IF(N33>0,"Win",IF(N33<0,"Loss","Breakeven")) -> Win | Q33: =IF(ROUND(K33,2)>ROUND(J33,2),"Yes","No") -> No | R33: Yes | S33: Entry without confirmation; trade still reached +1.8R | T33: 72077.1 | U33: Target hit | V33: 0.0501 | W33: =ROUND(W32+N32,2) -> 9884.25 | X33: =ROUND(W33*J33/100,2) -> 49.42 | Y33: R3 | Z33: =Z32+O33 -> 2.3212951 | AA33: =MAX(AA32,Z33) -> 2.5738009 | AB33: =Z33-AA33 -> -0.25250578 | AC33: =ROUND(W33+N33,2) -> 9972.32 | AD33: =MAX(AD32,AC33) -> 10266.68 | AE33: =(AC33-AD33)/AD33*100 -> -2.8671391 | AF33: =IF(O33>0,AF32+1,0) -> 1 | AG33: =IF(O33<0,AG32+1,0) -> 0
A34: T31 | B34: 46122 | C34: GBPUSD | D34: London/NY Overlap | E34: Trend Pullback | F34: Long | G34: 1.27765 | H34: 1.27388 | I34: 1.28707 | J34: 1 | K34: =V34*ABS(G34-H34)/W34*100 -> 0.99996759 | L34: =ROUND(V34*IF(F34="Long",1,-1)*(T34-G34),2) -> -107.66 | M34: 3.17 | N34: =ROUND(L34-M34,2) -> -110.83 | O34: =N34/X34 -> -1.111412 | P34: =IF(N34>0,"Win",IF(N34<0,"Loss","Breakeven")) -> Loss | Q34: =IF(ROUND(K34,2)>ROUND(J34,2),"Yes","No") -> No | R34: No | S34: Plan followed; stopped out | T34: 1.27358 | U34: Stop hit (slippage) | V34: 26450.92 | W34: =ROUND(W33+N33,2) -> 9972.32 | X34: =ROUND(W34*J34/100,2) -> 99.72 | Z34: =Z33+O34 -> 1.2098831 | AA34: =MAX(AA33,Z34) -> 2.5738009 | AB34: =Z34-AA34 -> -1.3639177 | AC34: =ROUND(W34+N34,2) -> 9861.49 | AD34: =MAX(AD33,AC34) -> 10266.68 | AE34: =(AC34-AD34)/AD34*100 -> -3.9466507 | AF34: =IF(O34>0,AF33+1,0) -> 0 | AG34: =IF(O34<0,AG33+1,0) -> 1
A35: T32 | B35: 46126 | C35: USDJPY | D35: London | E35: Range Reversal | F35: Short | G35: 147.421 | H35: 147.743 | I35: 146.906 | J35: 1 | K35: =V35*ABS(G35-H35)/W35*100 -> 0.99994301 | L35: =ROUND(V35*IF(F35="Long",1,-1)*(T35-G35),2) -> 157.71 | M35: 3.06 | N35: =ROUND(L35-M35,2) -> 154.65 | O35: =N35/X35 -> 1.5682994 | P35: =IF(N35>0,"Win",IF(N35<0,"Loss","Breakeven")) -> Win | Q35: =IF(ROUND(K35,2)>ROUND(J35,2),"Yes","No") -> No | R35: No | S35: Plan followed | T35: 146.906 | U35: Target hit | V35: 306.24 | W35: =ROUND(W34+N34,2) -> 9861.49 | X35: =ROUND(W35*J35/100,2) -> 98.61 | Z35: =Z34+O35 -> 2.7781825 | AA35: =MAX(AA34,Z35) -> 2.7781825 | AB35: =Z35-AA35 -> 0 | AC35: =ROUND(W35+N35,2) -> 10016.14 | AD35: =MAX(AD34,AC35) -> 10266.68 | AE35: =(AC35-AD35)/AD35*100 -> -2.4403215 | AF35: =IF(O35>0,AF34+1,0) -> 1 | AG35: =IF(O35<0,AG34+1,0) -> 0
A36: T33 | B36: 46127 | C36: USDJPY | D36: London/NY Overlap | E36: Range Reversal | F36: Long | G36: 149.371 | H36: 148.796 | I36: 150.234 | J36: 1 | K36: =V36*ABS(G36-H36)/W36*100 -> 1.2999319 | L36: =ROUND(V36*IF(F36="Long",1,-1)*(T36-G36),2) -> -130.2 | M36: 2.26 | N36: =ROUND(L36-M36,2) -> -132.46 | O36: =N36/X36 -> -1.322484 | P36: =IF(N36>0,"Win",IF(N36<0,"Loss","Breakeven")) -> Loss | Q36: =IF(ROUND(K36,2)>ROUND(J36,2),"Yes","No") -> Yes | R36: Yes | S36: Position size above plan by ~30% | T36: 148.796 | U36: Stop hit | V36: 226.44 | W36: =ROUND(W35+N35,2) -> 10016.14 | X36: =ROUND(W36*J36/100,2) -> 100.16 | Y36: R1 | Z36: =Z35+O36 -> 1.4556985 | AA36: =MAX(AA35,Z36) -> 2.7781825 | AB36: =Z36-AA36 -> -1.322484 | AC36: =ROUND(W36+N36,2) -> 9883.68 | AD36: =MAX(AD35,AC36) -> 10266.68 | AE36: =(AC36-AD36)/AD36*100 -> -3.7305146 | AF36: =IF(O36>0,AF35+1,0) -> 0 | AG36: =IF(O36<0,AG35+1,0) -> 1
A37: T34 | B37: 46128 | C37: GBPUSD | D37: London | E37: Range Reversal | F37: Long | G37: 1.29957 | H37: 1.29624 | I37: N/A | J37: 1 | K37: =V37*ABS(G37-H37)/W37*100 -> 1.0000323 | L37: =ROUND(V37*IF(F37="Long",1,-1)*(T37-G37),2) -> 98.84 | M37: 3.56 | N37: =ROUND(L37-M37,2) -> 95.28 | O37: =N37/X37 -> 0.96398219 | P37: =IF(N37>0,"Win",IF(N37<0,"Loss","Breakeven")) -> Win | Q37: =IF(ROUND(K37,2)>ROUND(J37,2),"Yes","No") -> No | R37: No | S37: Plan followed | T37: 1.3029 | U37: Trailing stop (documented) | V37: 29681.68 | W37: =ROUND(W36+N36,2) -> 9883.68 | X37: =ROUND(W37*J37/100,2) -> 98.84 | Z37: =Z36+O37 -> 2.4196807 | AA37: =MAX(AA36,Z37) -> 2.7781825 | AB37: =Z37-AA37 -> -0.35850183 | AC37: =ROUND(W37+N37,2) -> 9978.96 | AD37: =MAX(AD36,AC37) -> 10266.68 | AE37: =(AC37-AD37)/AD37*100 -> -2.8024639 | AF37: =IF(O37>0,AF36+1,0) -> 1 | AG37: =IF(O37<0,AG36+1,0) -> 0
A38: T35 | B38: 46129 | C38: XAUUSD | D38: New York | E38: Breakout | F38: Short | G38: 2643.6 | H38: 2650.69 | I38: 2625.88 | J38: 1 | K38: =V38*ABS(G38-H38)/W38*100 -> 0.9996663 | L38: =ROUND(V38*IF(F38="Long",1,-1)*(T38-G38),2) -> -99.76 | M38: 3.52 | N38: =ROUND(L38-M38,2) -> -103.28 | O38: =N38/X38 -> -1.0349734 | P38: =IF(N38>0,"Win",IF(N38<0,"Loss","Breakeven")) -> Loss | Q38: =IF(ROUND(K38,2)>ROUND(J38,2),"Yes","No") -> No | R38: No | S38: Plan followed; stopped out | T38: 2650.69 | U38: Stop hit | V38: 14.07 | W38: =ROUND(W37+N37,2) -> 9978.96 | X38: =ROUND(W38*J38/100,2) -> 99.79 | Z38: =Z37+O38 -> 1.3847072 | AA38: =MAX(AA37,Z38) -> 2.7781825 | AB38: =Z38-AA38 -> -1.3934753 | AC38: =ROUND(W38+N38,2) -> 9875.68 | AD38: =MAX(AD37,AC38) -> 10266.68 | AE38: =(AC38-AD38)/AD38*100 -> -3.8084366 | AF38: =IF(O38>0,AF37+1,0) -> 0 | AG38: =IF(O38<0,AG37+1,0) -> 1
A39: T36 | B39: 46133 | C39: XAUUSD | D39: London | E39: Trend Pullback | F39: Long | G39: 2676.15 | H39: 2662.99 | I39: 2694.57 | J39: 1 | K39: =V39*ABS(G39-H39)/W39*100 -> 0.99942485 | L39: =ROUND(V39*IF(F39="Long",1,-1)*(T39-G39),2) -> 138.15 | M39: 1.88 | N39: =ROUND(L39-M39,2) -> 136.27 | O39: =N39/X39 -> 1.3798096 | P39: =IF(N39>0,"Win",IF(N39<0,"Loss","Breakeven")) -> Win | Q39: =IF(ROUND(K39,2)>ROUND(J39,2),"Yes","No") -> No | R39: No | S39: Plan followed | T39: 2694.57 | U39: Target hit | V39: 7.5 | W39: =ROUND(W38+N38,2) -> 9875.68 | X39: =ROUND(W39*J39/100,2) -> 98.76 | Z39: =Z38+O39 -> 2.7645169 | AA39: =MAX(AA38,Z39) -> 2.7781825 | AB39: =Z39-AA39 -> -0.013665637 | AC39: =ROUND(W39+N39,2) -> 10011.95 | AD39: =MAX(AD38,AC39) -> 10266.68 | AE39: =(AC39-AD39)/AD39*100 -> -2.4811331 | AF39: =IF(O39>0,AF38+1,0) -> 1 | AG39: =IF(O39<0,AG38+1,0) -> 0
A40: T37 | B40: 46134 | C40: GBPUSD | D40: New York | E40: Discretionary Other | F40: Short | G40: 1.28847 | H40: 1.29265 | I40: 1.27802 | J40: 1 | K40: =V40*ABS(G40-H40)/W40*100 -> 1.0000049 | L40: =ROUND(V40*IF(F40="Long",1,-1)*(T40-G40),2) -> -100.12 | M40: 2.87 | N40: =ROUND(L40-M40,2) -> -102.99 | O40: =N40/X40 -> -1.0286656 | P40: =IF(N40>0,"Win",IF(N40<0,"Loss","Breakeven")) -> Loss | Q40: =IF(ROUND(K40,2)>ROUND(J40,2),"Yes","No") -> No | R40: Unclear | S40: Exit screenshot missing; cannot confirm stop was untouched | T40: 1.29265 | U40: Stop hit | V40: 23952.15 | W40: =ROUND(W39+N39,2) -> 10011.95 | X40: =ROUND(W40*J40/100,2) -> 100.12 | Y40: R4? | Z40: =Z39+O40 -> 1.7358513 | AA40: =MAX(AA39,Z40) -> 2.7781825 | AB40: =Z40-AA40 -> -1.0423312 | AC40: =ROUND(W40+N40,2) -> 9908.96 | AD40: =MAX(AD39,AC40) -> 10266.68 | AE40: =(AC40-AD40)/AD40*100 -> -3.4842812 | AF40: =IF(O40>0,AF39+1,0) -> 0 | AG40: =IF(O40<0,AG39+1,0) -> 1
...

Sheet Metrics & Definitions
A1: SIMULATED CASE STUDY — FICTIONAL DATA — NOT ACTUAL CLIENT RESULTS
A2: Live formulas on 'Trade Data'. Column C holds the value printed in the PDF; column D flags any disagreement.
A4: Metric | B4: Workbook value (formula) | C4: Value in PDF report | D4: Check | E4: Definition / formula
A5: BASIC PERFORMANCE
A6: Total trades | B6: =COUNTA('Trade Data'!$A$4:$A$43) -> 40 | C6: 40 | D6: =IF(ABS(B6-C6)<0.0051,"OK","CHECK") -> OK | E6: Count of trade records
A7: Winning trades | B7: =COUNTIF('Trade Data'!$N$4:$N$43,">0") -> 18 | C7: 18 | D7: =IF(ABS(B7-C7)<0.0051,"OK","CHECK") -> OK | E7: Net P/L (after costs) above zero
A8: Losing trades | B8: =COUNTIF('Trade Data'!$N$4:$N$43,"<0") -> 22 | C8: 22 | D8: =IF(ABS(B8-C8)<0.0051,"OK","CHECK") -> OK | E8: Net P/L below zero
A9: Win rate (%) | B9: =B7/B6*100 -> 45 | C9: 45 | D9: =IF(ABS(B9-C9)<0.0051,"OK","CHECK") -> OK | E9: Wins / Total trades x 100
A10: Profit on winners (R) | B10: =SUMIF('Trade Data'!$O$4:$O$43,">0") -> 27.686094 | C10: 27.6862 | D10: =IF(ABS(B10-C10)<0.0051,"OK","CHECK") -> OK | E10: Sum of net R on winning trades (the template's 'gross profit', after costs)
A11: Loss on losers (R) | B11: =SUMIF('Trade Data'!$O$4:$O$43,"<0") -> -23.566232 | C11: -23.5662 | D11: =IF(ABS(B11-C11)<0.0051,"OK","CHECK") -> OK | E11: Sum of net R on losing trades
A12: Net result (R) | B12: =B10+B11 -> 4.1198622 | C12: 4.12 | D12: =IF(ABS(B12-C12)<0.0051,"OK","CHECK") -> OK | E12: Profit - |Loss|
A13: Profit on winners (USD) | B13: =SUMIF('Trade Data'!$N$4:$N$43,">0") -> 2315.11 | C13: 2315.11 | D13: =IF(ABS(B13-C13)<0.0051,"OK","CHECK") -> OK | E13: Sum of net USD on winners
A14: Loss on losers (USD) | B14: =SUMIF('Trade Data'!$N$4:$N$43,"<0") -> -2170.64 | C14: -2170.64 | D14: =IF(ABS(B14-C14)<0.0051,"OK","CHECK") -> OK | E14: Sum of net USD on losers
A15: Net result (USD) | B15: =B13+B14 -> 144.47 | C15: 144.47 | D15: =IF(ABS(B15-C15)<0.0051,"OK","CHECK") -> OK | E15: Profit - |Loss|; equals sum of Net P/L column
A16: Pre-cost P/L (USD) | B16: =SUM('Trade Data'!$L$4:$L$43) -> 239.3 | C16: 239.3 | D16: =IF(ABS(B16-C16)<0.0051,"OK","CHECK") -> OK | E16: Sum of gross P/L before costs
A17: Transaction costs (USD) | B17: =SUM('Trade Data'!$M$4:$M$43) -> 94.83 | C17: 94.83 | D17: =IF(ABS(B17-C17)<0.0051,"OK","CHECK") -> OK | E17: Sum of round-turn spread costs
A18: Reconciliation: pre-cost - costs - net | B18: =ROUND(B16-B17-B15,2) -> 0 | C18: 0 | D18: =IF(ABS(B18-C18)<0.0051,"OK","CHECK") -> OK | E18: Must equal 0
A19: Average result per trade (R) | B19: =AVERAGE('Trade Data'!$O$4:$O$43) -> 0.10299655 | C19: 0.103 | D19: =IF(ABS(B19-C19)<0.0051,"OK","CHECK") -> OK | E19: Net R / Trades (expectancy)
A20: Average result per trade (USD) | B20: =AVERAGE('Trade Data'!$N$4:$N$43) -> 3.61175 | C20: 3.61175 | D20: =IF(ABS(B20-C20)<0.0051,"OK","CHECK") -> OK | E20: Net USD / Trades
A21: Average winning trade (R) | B21: =AVERAGEIF('Trade Data'!$O$4:$O$43,">0") -> 1.5381164 | C21: 1.538122 | D21: =IF(ABS(B21-C21)<0.0051,"OK","CHECK") -> OK | E21: Profit on winners / Wins
A22: Average losing trade (R) | B22: =AVERAGEIF('Trade Data'!$O$4:$O$43,"<0") -> -1.0711924 | C22: -1.071191 | D22: =IF(ABS(B22-C22)<0.0051,"OK","CHECK") -> OK | E22: Loss on losers / Losses
A23: Largest winning trade (R) | B23: =MAX('Trade Data'!$O$4:$O$43) -> 2.158405 | C23: 2.1584 | D23: =IF(ABS(B23-C23)<0.0051,"OK","CHECK") -> OK | E23: Maximum net R
A24: Largest losing trade (R) | B24: =MIN('Trade Data'!$O$4:$O$43) -> -1.5386606 | C24: -1.5387 | D24: =IF(ABS(B24-C24)<0.0051,"OK","CHECK") -> OK | E24: Minimum net R
A25: RISK AND REWARD
A26: Profit factor (R basis) | B26: =B10/ABS(B11) -> 1.1748206 | C26: 1.174827 | D26: =IF(ABS(B26-C26)<0.0051,"OK","CHECK") -> OK | E26: Profit / |Loss| in R
A27: Profit factor (USD basis) | B27: =B13/ABS(B14) -> 1.0665564 | C27: 1.066556 | D27: =IF(ABS(B27-C27)<0.0051,"OK","CHECK") -> OK | E27: Profit / |Loss| in USD
A28: Average win : average loss | B28: =B21/ABS(B22) -> 1.4358918 | C28: 1.435899 | D28: =IF(ABS(B28-C28)<0.0051,"OK","CHECK") -> OK | E28: Avg winning trade / |Avg losing trade| (R)
A29: Expectancy per trade (R) | B29: =B12/B6 -> 0.10299655 | C29: 0.103 | D29: =IF(ABS(B29-C29)<0.0051,"OK","CHECK") -> OK | E29: Total net R / Number of trades
A30: Break-even win rate (%) | B30: =100/(1+B28) -> 41.052726 | C30: 41.052601 | D30: =IF(ABS(B30-C30)<0.0051,"OK","CHECK") -> OK | E30: 1 / (1 + payoff ratio) x 100
A31: Standard deviation of trade R | B31: =STDEV('Trade Data'!$O$4:$O$43) -> 1.3545671 | C31: 1.35457 | D31: =IF(ABS(B31-C31)<0.0051,"OK","CHECK") -> OK | E31: Sample standard deviation
A32: Standard error of expectancy (R) | B32: =B31/SQRT(B6) -> 0.21417587 | C32: 0.214176 | D32: =IF(ABS(B32-C32)<0.0051,"OK","CHECK") -> OK | E32: SD / sqrt(n)
A33: 95% CI lower (R) | B33: =B29-TINV(0.05,B6-1)*B32 -> -0.33021503 | C33: -0.330215 | D33: =IF(ABS(B33-C33)<0.0051,"OK","CHECK") -> OK | E33: Mean - t(0.975, n-1) x SE
A34: 95% CI upper (R) | B34: =B29+TINV(0.05,B6-1)*B32 -> 0.53620814 | C34: 0.536215 | D34: =IF(ABS(B34-C34)<0.0051,"OK","CHECK") -> OK | E34: Mean + t(0.975, n-1) x SE
A35: Maximum drawdown (R) | B35: =MIN('Trade Data'!$AB$4:$AB$43) -> -3.7421455 | C35: -3.7421 | D35: =IF(ABS(B35-C35)<0.0051,"OK","CHECK") -> OK | E35: Largest peak-to-trough decline in cumulative R (peak includes the starting 0)
A36: Maximum drawdown (USD) | B36: =SUMPRODUCT(MIN('Trade Data'!$AC$4:$AC$43-'Trade Data'!$AD$4:$AD$43)) -> -405.19 | C36: -405.19 | D36: =IF(ABS(B36-C36)<0.0051,"OK","CHECK") -> OK | E36: Largest decline of equity from its running peak
A37: Maximum drawdown (% of peak equity) | B37: =MIN('Trade Data'!$AE$4:$AE$43) -> -3.9466507 | C37: -3.946651 | D37: =IF(ABS(B37-C37)<0.0051,"OK","CHECK") -> OK | E37: Account-equity drawdown; NOT the same as drawdown in R
A38: Average planned risk (% equity) | B38: =AVERAGE('Trade Data'!$J$4:$J$43) -> 0.8875 | C38: 0.8875 | D38: =IF(ABS(B38-C38)<0.0051,"OK","CHECK") -> OK | E38: Mean planned risk
A39: Average actual risk (% equity) | B39: =AVERAGE('Trade Data'!$K$4:$K$43) -> 0.90931516 | C39: 0.90935 | D39: =IF(ABS(B39-C39)<0.0051,"OK","CHECK") -> OK | E39: Mean actual risk
A40: Trades exceeding planned risk | B40: =COUNTIF('Trade Data'!$Q$4:$Q$43,"Yes") -> 4 | C40: 4 | D40: =IF(ABS(B40-C40)<0.0051,"OK","CHECK") -> OK | E40: Actual risk % > planned risk % (compared at 2 d.p.)
A41: as % of all trades | B41: =B40/B6*100 -> 10 | C41: 10 | D41: =IF(ABS(B41-C41)<0.0051,"OK","CHECK") -> OK | E41: Exceeded / Total trades x 100
...

Sheet Segments
A1: SIMULATED CASE STUDY — FICTIONAL DATA — NOT ACTUAL CLIENT RESULTS
A2: Segments are small (n < 20 for most). Descriptive only; do not read as a ranking. Counts and sums are live formulas.
A4: By setup
A5: Setup | B5: n | C5: Wins | D5: Win rate (%) | E5: Net R | F5: Expectancy (R) | G5: Profit factor (R) | H5: Net USD
A6: Breakout | B6: =COUNTIF('Trade Data'!$E$4:$E$43,A6) -> 8 | C6: =COUNTIFS('Trade Data'!$E$4:$E$43,A6,'Trade Data'!$O$4:$O$43,">0") -> 2 | D6: =C6/B6*100 -> 25 | E6: =SUMIF('Trade Data'!$E$4:$E$43,A6,'Trade Data'!$O$4:$O$43) -> -3.8027024 | F6: =E6/B6 -> -0.4753378 | G6: =IFERROR(SUMIFS('Trade Data'!$O$4:$O$43,'Trade Data'!$E$4:$E$43,A6,'Trade Data'!$O$4:$O$43,">0")/ABS(SUMIFS('Trade Data'!$O$4:$O$43,'Trade Data'!$E$4:$E$43,A6,'Trade Data'!$O$4:$O$43,"<0")),"n/a") -> 0.38263299 | H6: =SUMIF('Trade Data'!$E$4:$E$43,A6,'Trade Data'!$N$4:$N$43) -> -335.8
A7: Discretionary Other | B7: =COUNTIF('Trade Data'!$E$4:$E$43,A7) -> 7 | C7: =COUNTIFS('Trade Data'!$E$4:$E$43,A7,'Trade Data'!$O$4:$O$43,">0") -> 3 | D7: =C7/B7*100 -> 42.857143 | E7: =SUMIF('Trade Data'!$E$4:$E$43,A7,'Trade Data'!$O$4:$O$43) -> 1.4132072 | F7: =E7/B7 -> 0.20188674 | G7: =IFERROR(SUMIFS('Trade Data'!$O$4:$O$43,'Trade Data'!$E$4:$E$43,A7,'Trade Data'!$O$4:$O$43,">0")/ABS(SUMIFS('Trade Data'!$O$4:$O$43,'Trade Data'!$E$4:$E$43,A7,'Trade Data'!$O$4:$O$43,"<0")),"n/a") -> 1.3421457 | H7: =SUMIF('Trade Data'!$E$4:$E$43,A7,'Trade Data'!$N$4:$N$43) -> -51.99
A8: Range Reversal | B8: =COUNTIF('Trade Data'!$E$4:$E$43,A8) -> 8 | C8: =COUNTIFS('Trade Data'!$E$4:$E$43,A8,'Trade Data'!$O$4:$O$43,">0") -> 4 | D8: =C8/B8*100 -> 50 | E8: =SUMIF('Trade Data'!$E$4:$E$43,A8,'Trade Data'!$O$4:$O$43) -> 1.1705262 | F8: =E8/B8 -> 0.14631577 | G8: =IFERROR(SUMIFS('Trade Data'!$O$4:$O$43,'Trade Data'!$E$4:$E$43,A8,'Trade Data'!$O$4:$O$43,">0")/ABS(SUMIFS('Trade Data'!$O$4:$O$43,'Trade Data'!$E$4:$E$43,A8,'Trade Data'!$O$4:$O$43,"<0")),"n/a") -> 1.2599642 | H8: =SUMIF('Trade Data'!$E$4:$E$43,A8,'Trade Data'!$N$4:$N$43) -> 165.6
A9: Trend Pullback | B9: =COUNTIF('Trade Data'!$E$4:$E$43,A9) -> 17 | C9: =COUNTIFS('Trade Data'!$E$4:$E$43,A9,'Trade Data'!$O$4:$O$43,">0") -> 9 | D9: =C9/B9*100 -> 52.941176 | E9: =SUMIF('Trade Data'!$E$4:$E$43,A9,'Trade Data'!$O$4:$O$43) -> 5.3388312 | F9: =E9/B9 -> 0.3140489 | G9: =IFERROR(SUMIFS('Trade Data'!$O$4:$O$43,'Trade Data'!$E$4:$E$43,A9,'Trade Data'!$O$4:$O$43,">0")/ABS(SUMIFS('Trade Data'!$O$4:$O$43,'Trade Data'!$E$4:$E$43,A9,'Trade Data'!$O$4:$O$43,"<0")),"n/a") -> 1.6085099 | H9: =SUMIF('Trade Data'!$E$4:$E$43,A9,'Trade Data'!$N$4:$N$43) -> 366.66
A10: Total | B10: =SUM(B6:B9) -> 40 | E10: =SUM(E6:E9) -> 4.1198622
A12: By session
A13: Session | B13: n | C13: Wins | D13: Win rate (%) | E13: Net R | F13: Expectancy (R) | G13: Profit factor (R) | H13: Net USD
A14: Asian | B14: =COUNTIF('Trade Data'!$D$4:$D$43,A14) -> 5 | C14: =COUNTIFS('Trade Data'!$D$4:$D$43,A14,'Trade Data'!$O$4:$O$43,">0") -> 1 | D14: =C14/B14*100 -> 20 | E14: =SUMIF('Trade Data'!$D$4:$D$43,A14,'Trade Data'!$O$4:$O$43) -> -2.2022087 | F14: =E14/B14 -> -0.44044174 | G14: =IFERROR(SUMIFS('Trade Data'!$O$4:$O$43,'Trade Data'!$D$4:$D$43,A14,'Trade Data'!$O$4:$O$43,">0")/ABS(SUMIFS('Trade Data'!$O$4:$O$43,'Trade Data'!$D$4:$D$43,A14,'Trade Data'!$O$4:$O$43,"<0")),"n/a") -> 0.47318212 | H14: =SUMIF('Trade Data'!$D$4:$D$43,A14,'Trade Data'!$N$4:$N$43) -> -169.32
A15: London | B15: =COUNTIF('Trade Data'!$D$4:$D$43,A15) -> 13 | C15: =COUNTIFS('Trade Data'!$D$4:$D$43,A15,'Trade Data'!$O$4:$O$43,">0") -> 5 | D15: =C15/B15*100 -> 38.461538 | E15: =SUMIF('Trade Data'!$D$4:$D$43,A15,'Trade Data'!$O$4:$O$43) -> -3.273245 | F15: =E15/B15 -> -0.25178808 | G15: =IFERROR(SUMIFS('Trade Data'!$O$4:$O$43,'Trade Data'!$D$4:$D$43,A15,'Trade Data'!$O$4:$O$43,">0")/ABS(SUMIFS('Trade Data'!$O$4:$O$43,'Trade Data'!$D$4:$D$43,A15,'Trade Data'!$O$4:$O$43,"<0")),"n/a") -> 0.62558858 | H15: =SUMIF('Trade Data'!$D$4:$D$43,A15,'Trade Data'!$N$4:$N$43) -> -298.02
A16: London/NY Overlap | B16: =COUNTIF('Trade Data'!$D$4:$D$43,A16) -> 14 | C16: =COUNTIFS('Trade Data'!$D$4:$D$43,A16,'Trade Data'!$O$4:$O$43,">0") -> 8 | D16: =C16/B16*100 -> 57.142857 | E16: =SUMIF('Trade Data'!$D$4:$D$43,A16,'Trade Data'!$O$4:$O$43) -> 6.2330039 | F16: =E16/B16 -> 0.44521456 | G16: =IFERROR(SUMIFS('Trade Data'!$O$4:$O$43,'Trade Data'!$D$4:$D$43,A16,'Trade Data'!$O$4:$O$43,">0")/ABS(SUMIFS('Trade Data'!$O$4:$O$43,'Trade Data'!$D$4:$D$43,A16,'Trade Data'!$O$4:$O$43,"<0")),"n/a") -> 1.9550665 | H16: =SUMIF('Trade Data'!$D$4:$D$43,A16,'Trade Data'!$N$4:$N$43) -> 576.39
A17: New York | B17: =COUNTIF('Trade Data'!$D$4:$D$43,A17) -> 8 | C17: =COUNTIFS('Trade Data'!$D$4:$D$43,A17,'Trade Data'!$O$4:$O$43,">0") -> 4 | D17: =C17/B17*100 -> 50 | E17: =SUMIF('Trade Data'!$D$4:$D$43,A17,'Trade Data'!$O$4:$O$43) -> 3.362312 | F17: =E17/B17 -> 0.420289 | G17: =IFERROR(SUMIFS('Trade Data'!$O$4:$O$43,'Trade Data'!$D$4:$D$43,A17,'Trade Data'!$O$4:$O$43,">0")/ABS(SUMIFS('Trade Data'!$O$4:$O$43,'Trade Data'!$D$4:$D$43,A17,'Trade Data'!$O$4:$O$43,"<0")),"n/a") -> 1.816611 | H17: =SUMIF('Trade Data'!$D$4:$D$43,A17,'Trade Data'!$N$4:$N$43) -> 35.42
A18: Total | B18: =SUM(B14:B17) -> 40 | E18: =SUM(E14:E17) -> 4.1198622
A20: By instrument
A21: Instrument | B21: n | C21: Wins | D21: Win rate (%) | E21: Net R | F21: Expectancy (R) | G21: Profit factor (R) | H21: Net USD
A22: BTCUSD | B22: =COUNTIF('Trade Data'!$C$4:$C$43,A22) -> 9 | C22: =COUNTIFS('Trade Data'!$C$4:$C$43,A22,'Trade Data'!$O$4:$O$43,">0") -> 5 | D22: =C22/B22*100 -> 55.555556 | E22: =SUMIF('Trade Data'!$C$4:$C$43,A22,'Trade Data'!$O$4:$O$43) -> 4.810178 | F22: =E22/B22 -> 0.53446422 | G22: =IFERROR(SUMIFS('Trade Data'!$O$4:$O$43,'Trade Data'!$C$4:$C$43,A22,'Trade Data'!$O$4:$O$43,">0")/ABS(SUMIFS('Trade Data'!$O$4:$O$43,'Trade Data'!$C$4:$C$43,A22,'Trade Data'!$O$4:$O$43,"<0")),"n/a") -> 2.1572994 | H22: =SUMIF('Trade Data'!$C$4:$C$43,A22,'Trade Data'!$N$4:$N$43) -> 235.92
A23: EURUSD | B23: =COUNTIF('Trade Data'!$C$4:$C$43,A23) -> 8 | C23: =COUNTIFS('Trade Data'!$C$4:$C$43,A23,'Trade Data'!$O$4:$O$43,">0") -> 5 | D23: =C23/B23*100 -> 62.5 | E23: =SUMIF('Trade Data'!$C$4:$C$43,A23,'Trade Data'!$O$4:$O$43) -> 4.4501964 | F23: =E23/B23 -> 0.55627455 | G23: =IFERROR(SUMIFS('Trade Data'!$O$4:$O$43,'Trade Data'!$C$4:$C$43,A23,'Trade Data'!$O$4:$O$43,">0")/ABS(SUMIFS('Trade Data'!$O$4:$O$43,'Trade Data'!$C$4:$C$43,A23,'Trade Data'!$O$4:$O$43,"<0")),"n/a") -> 2.444803 | H23: =SUMIF('Trade Data'!$C$4:$C$43,A23,'Trade Data'!$N$4:$N$43) -> 442.44
A24: GBPUSD | B24: =COUNTIF('Trade Data'!$C$4:$C$43,A24) -> 5 | C24: =COUNTIFS('Trade Data'!$C$4:$C$43,A24,'Trade Data'!$O$4:$O$43,">0") -> 1 | D24: =C24/B24*100 -> 20 | E24: =SUMIF('Trade Data'!$C$4:$C$43,A24,'Trade Data'!$O$4:$O$43) -> -3.2417016 | F24: =E24/B24 -> -0.64834031 | G24: =IFERROR(SUMIFS('Trade Data'!$O$4:$O$43,'Trade Data'!$C$4:$C$43,A24,'Trade Data'!$O$4:$O$43,">0")/ABS(SUMIFS('Trade Data'!$O$4:$O$43,'Trade Data'!$C$4:$C$43,A24,'Trade Data'!$O$4:$O$43,"<0")),"n/a") -> 0.22920939 | H24: =SUMIF('Trade Data'!$C$4:$C$43,A24,'Trade Data'!$N$4:$N$43) -> -327.51
A25: USDJPY | B25: =COUNTIF('Trade Data'!$C$4:$C$43,A25) -> 11 | C25: =COUNTIFS('Trade Data'!$C$4:$C$43,A25,'Trade Data'!$O$4:$O$43,">0") -> 5 | D25: =C25/B25*100 -> 45.454545 | E25: =SUMIF('Trade Data'!$C$4:$C$43,A25,'Trade Data'!$O$4:$O$43) -> 0.74778847 | F25: =E25/B25 -> 0.06798077 | G25: =IFERROR(SUMIFS('Trade Data'!$O$4:$O$43,'Trade Data'!$C$4:$C$43,A25,'Trade Data'!$O$4:$O$43,">0")/ABS(SUMIFS('Trade Data'!$O$4:$O$43,'Trade Data'!$C$4:$C$43,A25,'Trade Data'!$O$4:$O$43,"<0")),"n/a") -> 1.1162942 | H25: =SUMIF('Trade Data'!$C$4:$C$43,A25,'Trade Data'!$N$4:$N$43) -> 66.56
A26: XAUUSD | B26: =COUNTIF('Trade Data'!$C$4:$C$43,A26) -> 7 | C26: =COUNTIFS('Trade Data'!$C$4:$C$43,A26,'Trade Data'!$O$4:$O$43,">0") -> 2 | D26: =C26/B26*100 -> 28.571429 | E26: =SUMIF('Trade Data'!$C$4:$C$43,A26,'Trade Data'!$O$4:$O$43) -> -2.6465991 | F26: =E26/B26 -> -0.37808558 | G26: =IFERROR(SUMIFS('Trade Data'!$O$4:$O$43,'Trade Data'!$C$4:$C$43,A26,'Trade Data'!$O$4:$O$43,">0")/ABS(SUMIFS('Trade Data'!$O$4:$O$43,'Trade Data'!$C$4:$C$43,A26,'Trade Data'!$O$4:$O$43,"<0")),"n/a") -> 0.53518553 | H26: =SUMIF('Trade Data'!$C$4:$C$43,A26,'Trade Data'!$N$4:$N$43) -> -272.94
A27: Total | B27: =SUM(B22:B26) -> 40 | E27: =SUM(E22:E26) -> 4.1198622
A29: By direction
A30: Direction | B30: n | C30: Wins | D30: Win rate (%) | E30: Net R | F30: Expectancy (R) | G30: Profit factor (R) | H30: Net USD
A31: Long | B31: =COUNTIF('Trade Data'!$F$4:$F$43,A31) -> 26 | C31: =COUNTIFS('Trade Data'!$F$4:$F$43,A31,'Trade Data'!$O$4:$O$43,">0") -> 14 | D31: =C31/B31*100 -> 53.846154 | E31: =SUMIF('Trade Data'!$F$4:$F$43,A31,'Trade Data'!$O$4:$O$43) -> 7.680578 | F31: =E31/B31 -> 0.29540684 | G31: =IFERROR(SUMIFS('Trade Data'!$O$4:$O$43,'Trade Data'!$F$4:$F$43,A31,'Trade Data'!$O$4:$O$43,">0")/ABS(SUMIFS('Trade Data'!$O$4:$O$43,'Trade Data'!$F$4:$F$43,A31,'Trade Data'!$O$4:$O$43,"<0")),"n/a") -> 1.5773819 | H31: =SUMIF('Trade Data'!$F$4:$F$43,A31,'Trade Data'!$N$4:$N$43) -> 554.92
A32: Short | B32: =COUNTIF('Trade Data'!$F$4:$F$43,A32) -> 14 | C32: =COUNTIFS('Trade Data'!$F$4:$F$43,A32,'Trade Data'!$O$4:$O$43,">0") -> 4 | D32: =C32/B32*100 -> 28.571429 | E32: =SUMIF('Trade Data'!$F$4:$F$43,A32,'Trade Data'!$O$4:$O$43) -> -3.5607158 | F32: =E32/B32 -> -0.25433684 | G32: =IFERROR(SUMIFS('Trade Data'!$O$4:$O$43,'Trade Data'!$F$4:$F$43,A32,'Trade Data'!$O$4:$O$43,">0")/ABS(SUMIFS('Trade Data'!$O$4:$O$43,'Trade Data'!$F$4:$F$43,A32,'Trade Data'!$O$4:$O$43,"<0")),"n/a") -> 0.65308048 | H32: =SUMIF('Trade Data'!$F$4:$F$43,A32,'Trade Data'!$N$4:$N$43) -> -410.45
A33: Total | B33: =SUM(B31:B32) -> 40 | E33: =SUM(E31:E32) -> 4.1198622
A35: By rule status
A36: Rule status | B36: n | C36: Wins | D36: Win rate (%) | E36: Net R | F36: Expectancy (R) | G36: Profit factor (R) | H36: Net USD
A37: No | B37: =COUNTIF('Trade Data'!$R$4:$R$43,A37) -> 30 | C37: =COUNTIFS('Trade Data'!$R$4:$R$43,A37,'Trade Data'!$O$4:$O$43,">0") -> 15 | D37: =C37/B37*100 -> 50 | E37: =SUMIF('Trade Data'!$R$4:$R$43,A37,'Trade Data'!$O$4:$O$43) -> 9.2741928 | F37: =E37/B37 -> 0.30913976 | G37: =IFERROR(SUMIFS('Trade Data'!$O$4:$O$43,'Trade Data'!$R$4:$R$43,A37,'Trade Data'!$O$4:$O$43,">0")/ABS(SUMIFS('Trade Data'!$O$4:$O$43,'Trade Data'!$R$4:$R$43,A37,'Trade Data'!$O$4:$O$43,"<0")),"n/a") -> 1.5988363 | H37: =SUMIF('Trade Data'!$R$4:$R$43,A37,'Trade Data'!$N$4:$N$43) -> 700.83
A38: Unclear | B38: =COUNTIF('Trade Data'!$R$4:$R$43,A38) -> 2 | C38: =COUNTIFS('Trade Data'!$R$4:$R$43,A38,'Trade Data'!$O$4:$O$43,">0") -> 0 | D38: =C38/B38*100 -> 0 | E38: =SUMIF('Trade Data'!$R$4:$R$43,A38,'Trade Data'!$O$4:$O$43) -> -2.0514596 | F38: =E38/B38 -> -1.0257298 | G38: =IFERROR(SUMIFS('Trade Data'!$O$4:$O$43,'Trade Data'!$R$4:$R$43,A38,'Trade Data'!$O$4:$O$43,">0")/ABS(SUMIFS('Trade Data'!$O$4:$O$43,'Trade Data'!$R$4:$R$43,A38,'Trade Data'!$O$4:$O$43,"<0")),"n/a") -> 0 | H38: =SUMIF('Trade Data'!$R$4:$R$43,A38,'Trade Data'!$N$4:$N$43) -> -207.54
A39: Yes | B39: =COUNTIF('Trade Data'!$R$4:$R$43,A39) -> 8 | C39: =COUNTIFS('Trade Data'!$R$4:$R$43,A39,'Trade Data'!$O$4:$O$43,">0") -> 3 | D39: =C39/B39*100 -> 37.5 | E39: =SUMIF('Trade Data'!$R$4:$R$43,A39,'Trade Data'!$O$4:$O$43) -> -3.102871 | F39: =E39/B39 -> -0.38785888 | G39: =IFERROR(SUMIFS('Trade Data'!$O$4:$O$43,'Trade Data'!$R$4:$R$43,A39,'Trade Data'!$O$4:$O$43,">0")/ABS(SUMIFS('Trade Data'!$O$4:$O$43,'Trade Data'!$R$4:$R$43,A39,'Trade Data'!$O$4:$O$43,"<0")),"n/a") -> 0.48523537 | H39: =SUMIF('Trade Data'!$R$4:$R$43,A39,'Trade Data'!$N$4:$N$43) -> -348.82
A40: Total | B40: =SUM(B37:B39) -> 40 | E40: =SUM(E37:E39) -> 4.1198622
A42: By planned-risk status
A43: Planned-risk status | B43: n | C43: Wins | D43: Win rate (%) | E43: Net R | F43: Expectancy (R) | G43: Profit factor (R) | H43: Net USD
A44: No | B44: =COUNTIF('Trade Data'!$Q$4:$Q$43,A44) -> 36 | C44: =COUNTIFS('Trade Data'!$Q$4:$Q$43,A44,'Trade Data'!$O$4:$O$43,">0") -> 17 | D44: =C44/B44*100 -> 47.222222 | E44: =SUMIF('Trade Data'!$Q$4:$Q$43,A44,'Trade Data'!$O$4:$O$43) -> 5.9002685 | F44: =E44/B44 -> 0.16389635 | G44: =IFERROR(SUMIFS('Trade Data'!$O$4:$O$43,'Trade Data'!$Q$4:$Q$43,A44,'Trade Data'!$O$4:$O$43,">0")/ABS(SUMIFS('Trade Data'!$O$4:$O$43,'Trade Data'!$Q$4:$Q$43,A44,'Trade Data'!$O$4:$O$43,"<0")),"n/a") -> 1.3003865 | H44: =SUMIF('Trade Data'!$Q$4:$Q$43,A44,'Trade Data'!$N$4:$N$43) -> 431.72
A45: Yes | B45: =COUNTIF('Trade Data'!$Q$4:$Q$43,A45) -> 4 | C45: =COUNTIFS('Trade Data'!$Q$4:$Q$43,A45,'Trade Data'!$O$4:$O$43,">0") -> 1 | D45: =C45/B45*100 -> 25 | E45: =SUMIF('Trade Data'!$Q$4:$Q$43,A45,'Trade Data'!$O$4:$O$43) -> -1.7804063 | F45: =E45/B45 -> -0.44510158 | G45: =IFERROR(SUMIFS('Trade Data'!$O$4:$O$43,'Trade Data'!$Q$4:$Q$43,A45,'Trade Data'!$O$4:$O$43,">0")/ABS(SUMIFS('Trade Data'!$O$4:$O$43,'Trade Data'!$Q$4:$Q$43,A45,'Trade Data'!$O$4:$O$43,"<0")),"n/a") -> 0.54627534 | H45: =SUMIF('Trade Data'!$Q$4:$Q$43,A45,'Trade Data'!$N$4:$N$43) -> -287.25
A46: Total | B46: =SUM(B44:B45) -> 40 | E46: =SUM(E44:E45) -> 4.1198622
